Backup failed for Site library.test. Database or site_config.json may be corrupted
Traceback (most recent call last):
  File "/home/goblin/frappe-bench/apps/frappe/frappe/commands/site.py", line 429, in backup
    odb = scheduled_backup(
  File "/home/goblin/frappe-bench/apps/frappe/frappe/utils/backups.py", line 516, in scheduled_backup
    odb = new_backup(
  File "/home/goblin/frappe-bench/apps/frappe/frappe/utils/backups.py", line 550, in new_backup
    odb = BackupGenerator(
  File "/home/goblin/frappe-bench/apps/frappe/frappe/utils/backups.py", line 85, in __init__
    self.setup_backup_tables()
  File "/home/goblin/frappe-bench/apps/frappe/frappe/utils/backups.py", line 119, in setup_backup_tables
    existing_tables = frappe.db.get_tables()
  File "/home/goblin/frappe-bench/apps/frappe/frappe/database/database.py", line 732, in get_tables
    table_rows = self.sql("""
  File "/home/goblin/frappe-bench/apps/frappe/frappe/database/database.py", line 121, in sql
    self.connect()
  File "/home/goblin/frappe-bench/apps/frappe/frappe/database/database.py", line 71, in connect
    self._conn = self.get_connection()
  File "/home/goblin/frappe-bench/apps/frappe/frappe/database/mariadb/database.py", line 74, in get_connection
    conn = pymysql.connect(
  File "/home/goblin/frappe-bench/env/lib/python3.9/site-packages/pymysql/connections.py", line 353, in __init__
    self.connect()
  File "/home/goblin/frappe-bench/env/lib/python3.9/site-packages/pymysql/connections.py", line 633, in connect
    self._request_authentication()
  File "/home/goblin/frappe-bench/env/lib/python3.9/site-packages/pymysql/connections.py", line 907, in _request_authentication
    auth_packet = self._read_packet()
  File "/home/goblin/frappe-bench/env/lib/python3.9/site-packages/pymysql/connections.py", line 725, in _read_packet
    packet.raise_for_error()
  File "/home/goblin/frappe-bench/env/lib/python3.9/site-packages/pymysql/protocol.py", line 221, in raise_for_error
    err.raise_mysql_exception(self._data)
  File "/home/goblin/frappe-bench/env/lib/python3.9/site-packages/pymysql/err.py", line 143, in raise_mysql_exception
    raise errorclass(errno, errval)
pymysql.err.OperationalError: (1045, "Access denied for user '_dc31ce23adcd140a'@'localhost' (using password: YES)")

mysqldump --single-transaction --quick --lock-tables=false -u _dc31ce23adcd140a -pH4r6fYHWpzkjlmPD _dc31ce23adcd140a -h 127.0.0.1 -P 3306   | /usr/bin/gzip >> ./library.test/private/backups/20211008_180002-library_test-database.sql.gz

Backup Summary for library.test at 2021-10-08 18:00:03.876964
Config  : ./library.test/private/backups/20211008_180002-library_test-site_config_backup.json 94.0B
Database: ./library.test/private/backups/20211008_180002-library_test-database.sql.gz         260.7KiB
Backup for Site library.test has been successfully completed
mysqldump --single-transaction --quick --lock-tables=false -u _dc31ce23adcd140a -pH4r6fYHWpzkjlmPD _dc31ce23adcd140a -h 127.0.0.1 -P 3306   | /usr/bin/gzip >> ./library.test/private/backups/20211009_000001-library_test-database.sql.gz

Backup Summary for library.test at 2021-10-09 00:00:02.274419
Config  : ./library.test/private/backups/20211009_000001-library_test-site_config_backup.json 94.0B
Database: ./library.test/private/backups/20211009_000001-library_test-database.sql.gz         267.7KiB
Backup for Site library.test has been successfully completed
mysqldump --single-transaction --quick --lock-tables=false -u _dc31ce23adcd140a -pH4r6fYHWpzkjlmPD _dc31ce23adcd140a -h 127.0.0.1 -P 3306   | /usr/bin/gzip >> ./library.test/private/backups/20211009_060002-library_test-database.sql.gz

Backup Summary for library.test at 2021-10-09 06:00:02.612547
Config  : ./library.test/private/backups/20211009_060002-library_test-site_config_backup.json 94.0B
Database: ./library.test/private/backups/20211009_060002-library_test-database.sql.gz         275.0KiB
Backup for Site library.test has been successfully completed
mysqldump --single-transaction --quick --lock-tables=false -u _dc31ce23adcd140a -pH4r6fYHWpzkjlmPD _dc31ce23adcd140a -h 127.0.0.1 -P 3306   | /usr/bin/gzip >> ./library.test/private/backups/20211009_120002-library_test-database.sql.gz

Backup Summary for library.test at 2021-10-09 12:00:02.774453
Config  : ./library.test/private/backups/20211009_120002-library_test-site_config_backup.json 94.0B
Database: ./library.test/private/backups/20211009_120002-library_test-database.sql.gz         275.0KiB
Backup for Site library.test has been successfully completed
