Exception in thread Thread-1:
Traceback (most recent call last):
  File "/usr/lib/python3.9/threading.py", line 973, in _bootstrap_inner
    self.run()
  File "/home/goblin/frappe-bench/env/lib/python3.9/site-packages/redis/client.py", line 3718, in run
Exception in thread Thread-1:
Traceback (most recent call last):
  File "/usr/lib/python3.9/threading.py", line 973, in _bootstrap_inner
    self.run()
  File "/home/goblin/frappe-bench/env/lib/python3.9/site-packages/redis/client.py", line 3718, in run
    pubsub.get_message(ignore_subscribe_messages=True,
  File "/home/goblin/frappe-bench/env/lib/python3.9/site-packages/redis/client.py", line 3617, in get_message
    pubsub.get_message(ignore_subscribe_messages=True,
  File "/home/goblin/frappe-bench/env/lib/python3.9/site-packages/redis/client.py", line 3617, in get_message
    response = self.parse_response(block=False, timeout=timeout)
  File "/home/goblin/frappe-bench/env/lib/python3.9/site-packages/redis/client.py", line 3503, in parse_response
    response = self.parse_response(block=False, timeout=timeout)
  File "/home/goblin/frappe-bench/env/lib/python3.9/site-packages/redis/client.py", line 3503, in parse_response
    if not block and not conn.can_read(timeout=timeout):
  File "/home/goblin/frappe-bench/env/lib/python3.9/site-packages/redis/connection.py", line 734, in can_read
    return self._parser.can_read(timeout)
  File "/home/goblin/frappe-bench/env/lib/python3.9/site-packages/redis/connection.py", line 321, in can_read
    return self._buffer and self._buffer.can_read(timeout)
  File "/home/goblin/frappe-bench/env/lib/python3.9/site-packages/redis/connection.py", line 230, in can_read
    self._read_from_socket(timeout=timeout,
  File "/home/goblin/frappe-bench/env/lib/python3.9/site-packages/redis/connection.py", line 201, in _read_from_socket
    raise ConnectionError(SERVER_CLOSED_CONNECTION_ERROR)
redis.exceptions.ConnectionError: Connection closed by server.
    if not block and not conn.can_read(timeout=timeout):
  File "/home/goblin/frappe-bench/env/lib/python3.9/site-packages/redis/connection.py", line 734, in can_read
    return self._parser.can_read(timeout)
  File "/home/goblin/frappe-bench/env/lib/python3.9/site-packages/redis/connection.py", line 321, in can_read
    return self._buffer and self._buffer.can_read(timeout)
  File "/home/goblin/frappe-bench/env/lib/python3.9/site-packages/redis/connection.py", line 230, in can_read
    self._read_from_socket(timeout=timeout,
  File "/home/goblin/frappe-bench/env/lib/python3.9/site-packages/redis/connection.py", line 201, in _read_from_socket
    raise ConnectionError(SERVER_CLOSED_CONNECTION_ERROR)
redis.exceptions.ConnectionError: Connection closed by server.
Exception in thread Thread-1:
Traceback (most recent call last):
  File "/usr/lib/python3.9/threading.py", line 973, in _bootstrap_inner
    self.run()
  File "/home/goblin/frappe-bench/env/lib/python3.9/site-packages/redis/client.py", line 3718, in run
    pubsub.get_message(ignore_subscribe_messages=True,
  File "/home/goblin/frappe-bench/env/lib/python3.9/site-packages/redis/client.py", line 3617, in get_message
    response = self.parse_response(block=False, timeout=timeout)
  File "/home/goblin/frappe-bench/env/lib/python3.9/site-packages/redis/client.py", line 3503, in parse_response
    if not block and not conn.can_read(timeout=timeout):
  File "/home/goblin/frappe-bench/env/lib/python3.9/site-packages/redis/connection.py", line 734, in can_read
    return self._parser.can_read(timeout)
  File "/home/goblin/frappe-bench/env/lib/python3.9/site-packages/redis/connection.py", line 321, in can_read
    return self._buffer and self._buffer.can_read(timeout)
  File "/home/goblin/frappe-bench/env/lib/python3.9/site-packages/redis/connection.py", line 230, in can_read
    self._read_from_socket(timeout=timeout,
  File "/home/goblin/frappe-bench/env/lib/python3.9/site-packages/redis/connection.py", line 201, in _read_from_socket
    raise ConnectionError(SERVER_CLOSED_CONNECTION_ERROR)
redis.exceptions.ConnectionError: Connection closed by server.
Exception in thread Thread-1:
Traceback (most recent call last):
Exception in thread   File "/usr/lib/python3.9/threading.py", line 973, in _bootstrap_inner
Thread-1:
Traceback (most recent call last):
  File "/usr/lib/python3.9/threading.py", line 973, in _bootstrap_inner
    self.run()
      File "/home/goblin/frappe-bench/env/lib/python3.9/site-packages/redis/client.py", line 3718, in run
    pubsub.get_message(ignore_subscribe_messages=True,
  File "/home/goblin/frappe-bench/env/lib/python3.9/site-packages/redis/client.py", line 3617, in get_message
    response = self.parse_response(block=False, timeout=timeout)
  File "/home/goblin/frappe-bench/env/lib/python3.9/site-packages/redis/client.py", line 3503, in parse_response
    if not block and not conn.can_read(timeout=timeout):
  File "/home/goblin/frappe-bench/env/lib/python3.9/site-packages/redis/connection.py", line 734, in can_read
    return self._parser.can_read(timeout)
  File "/home/goblin/frappe-bench/env/lib/python3.9/site-packages/redis/connection.py", line 321, in can_read
    return self._buffer and self._buffer.can_read(timeout)
  File "/home/goblin/frappe-bench/env/lib/python3.9/site-packages/redis/connection.py", line 230, in can_read
    self._read_from_socket(timeout=timeout,
  File "/home/goblin/frappe-bench/env/lib/python3.9/site-packages/redis/connection.py", line 201, in _read_from_socket
    raise ConnectionError(SERVER_CLOSED_CONNECTION_ERROR)
redis.exceptions.ConnectionError: Connection closed by server.
self.run()
  File "/home/goblin/frappe-bench/env/lib/python3.9/site-packages/redis/client.py", line 3718, in run
    pubsub.get_message(ignore_subscribe_messages=True,
  File "/home/goblin/frappe-bench/env/lib/python3.9/site-packages/redis/client.py", line 3617, in get_message
Exception in thread Thread-1:
Traceback (most recent call last):
  File "/usr/lib/python3.9/threading.py", line 973, in _bootstrap_inner
    self.run()
  File "/home/goblin/frappe-bench/env/lib/python3.9/site-packages/redis/client.py", line 3718, in run
    pubsub.get_message(ignore_subscribe_messages=True,
  File "/home/goblin/frappe-bench/env/lib/python3.9/site-packages/redis/client.py", line 3617, in get_message
    response = self.parse_response(block=False, timeout=timeout)
  File "/home/goblin/frappe-bench/env/lib/python3.9/site-packages/redis/client.py", line 3503, in parse_response
    if not block and not conn.can_read(timeout=timeout):
  File "/home/goblin/frappe-bench/env/lib/python3.9/site-packages/redis/connection.py", line 734, in can_read
    return self._parser.can_read(timeout)
  File "/home/goblin/frappe-bench/env/lib/python3.9/site-packages/redis/connection.py", line 321, in can_read
    return self._buffer and self._buffer.can_read(timeout)
  File "/home/goblin/frappe-bench/env/lib/python3.9/site-packages/redis/connection.py", line 230, in can_read
    self._read_from_socket(timeout=timeout,
  File "/home/goblin/frappe-bench/env/lib/python3.9/site-packages/redis/connection.py", line 201, in _read_from_socket
    raise ConnectionError(SERVER_CLOSED_CONNECTION_ERROR)
redis.exceptions.ConnectionError: Connection closed by server.
    response = self.parse_response(block=False, timeout=timeout)
  File "/home/goblin/frappe-bench/env/lib/python3.9/site-packages/redis/client.py", line 3503, in parse_response
    if not block and not conn.can_read(timeout=timeout):
  File "/home/goblin/frappe-bench/env/lib/python3.9/site-packages/redis/connection.py", line 734, in can_read
    return self._parser.can_read(timeout)
  File "/home/goblin/frappe-bench/env/lib/python3.9/site-packages/redis/connection.py", line 321, in can_read
    return self._buffer and self._buffer.can_read(timeout)
  File "/home/goblin/frappe-bench/env/lib/python3.9/site-packages/redis/connection.py", line 230, in can_read
    self._read_from_socket(timeout=timeout,
  File "/home/goblin/frappe-bench/env/lib/python3.9/site-packages/redis/connection.py", line 201, in _read_from_socket
    raise ConnectionError(SERVER_CLOSED_CONNECTION_ERROR)
redis.exceptions.ConnectionError: Connection closed by server.
Exception in thread Thread-1:
Traceback (most recent call last):
  File "/usr/lib/python3.9/threading.py", line 973, in _bootstrap_inner
    self.run()
  File "/home/goblin/frappe-bench/env/lib/python3.9/site-packages/redis/client.py", line 3718, in run
Exception in thread Thread-1:
Traceback (most recent call last):
  File "/usr/lib/python3.9/threading.py", line 973, in _bootstrap_inner
    self.run()
  File "/home/goblin/frappe-bench/env/lib/python3.9/site-packages/redis/client.py", line 3718, in run
    pubsub.get_message(ignore_subscribe_messages=True,
  File "/home/goblin/frappe-bench/env/lib/python3.9/site-packages/redis/client.py", line 3617, in get_message
    response = self.parse_response(block=False, timeout=timeout)
  File "/home/goblin/frappe-bench/env/lib/python3.9/site-packages/redis/client.py", line 3503, in parse_response
    if not block and not conn.can_read(timeout=timeout):
  File "/home/goblin/frappe-bench/env/lib/python3.9/site-packages/redis/connection.py", line 734, in can_read
    return self._parser.can_read(timeout)
  File "/home/goblin/frappe-bench/env/lib/python3.9/site-packages/redis/connection.py", line 321, in can_read
    return self._buffer and self._buffer.can_read(timeout)
  File "/home/goblin/frappe-bench/env/lib/python3.9/site-packages/redis/connection.py", line 230, in can_read
    self._read_from_socket(timeout=timeout,
  File "/home/goblin/frappe-bench/env/lib/python3.9/site-packages/redis/connection.py", line 201, in _read_from_socket
    raise ConnectionError(SERVER_CLOSED_CONNECTION_ERROR)
redis.exceptions.ConnectionError: Connection closed by server.
    pubsub.get_message(ignore_subscribe_messages=True,
  File "/home/goblin/frappe-bench/env/lib/python3.9/site-packages/redis/client.py", line 3617, in get_message
    response = self.parse_response(block=False, timeout=timeout)
  File "/home/goblin/frappe-bench/env/lib/python3.9/site-packages/redis/client.py", line 3503, in parse_response
    if not block and not conn.can_read(timeout=timeout):
  File "/home/goblin/frappe-bench/env/lib/python3.9/site-packages/redis/connection.py", line 734, in can_read
    return self._parser.can_read(timeout)
  File "/home/goblin/frappe-bench/env/lib/python3.9/site-packages/redis/connection.py", line 321, in can_read
    return self._buffer and self._buffer.can_read(timeout)
  File "/home/goblin/frappe-bench/env/lib/python3.9/site-packages/redis/connection.py", line 230, in can_read
    self._read_from_socket(timeout=timeout,
  File "/home/goblin/frappe-bench/env/lib/python3.9/site-packages/redis/connection.py", line 201, in _read_from_socket
    raise ConnectionError(SERVER_CLOSED_CONNECTION_ERROR)
redis.exceptions.ConnectionError: Connection closed by server.
Exception in thread Thread-1:
Traceback (most recent call last):
  File "/usr/lib/python3.9/threading.py", line 973, in _bootstrap_inner
    self.run()
  File "/home/goblin/frappe-bench/env/lib/python3.9/site-packages/redis/client.py", line 3718, in run
    pubsub.get_message(ignore_subscribe_messages=True,
  File "/home/goblin/frappe-bench/env/lib/python3.9/site-packages/redis/client.py", line 3617, in get_message
    response = self.parse_response(block=False, timeout=timeout)
  File "/home/goblin/frappe-bench/env/lib/python3.9/site-packages/redis/client.py", line 3503, in parse_response
    if not block and not conn.can_read(timeout=timeout):
  File "/home/goblin/frappe-bench/env/lib/python3.9/site-packages/redis/connection.py", line 734, in can_read
    return self._parser.can_read(timeout)
  File "/home/goblin/frappe-bench/env/lib/python3.9/site-packages/redis/connection.py", line 321, in can_read
    return self._buffer and self._buffer.can_read(timeout)
  File "/home/goblin/frappe-bench/env/lib/python3.9/site-packages/redis/connection.py", line 230, in can_read
    self._read_from_socket(timeout=timeout,
  File "/home/goblin/frappe-bench/env/lib/python3.9/site-packages/redis/connection.py", line 201, in _read_from_socket
    raise ConnectionError(SERVER_CLOSED_CONNECTION_ERROR)
redis.exceptions.ConnectionError: Connection closed by server.
18:18:08 Traceback (most recent call last):
  File "/home/goblin/frappe-bench/env/lib/python3.9/site-packages/rq/worker.py", line 1013, in perform_job
    rv = job.perform()
  File "/home/goblin/frappe-bench/env/lib/python3.9/site-packages/rq/job.py", line 709, in perform
    self._result = self._execute()
  File "/home/goblin/frappe-bench/env/lib/python3.9/site-packages/rq/job.py", line 732, in _execute
    result = self.func(*self.args, **self.kwargs)
  File "/home/goblin/frappe-bench/apps/frappe/frappe/utils/background_jobs.py", line 106, in execute_job
    method(**kwargs)
  File "/home/goblin/frappe-bench/apps/frappe/frappe/core/doctype/user/user.py", line 991, in create_contact
    contact.insert(ignore_permissions=True, ignore_links=ignore_links, ignore_mandatory=ignore_mandatory)
  File "/home/goblin/frappe-bench/apps/frappe/frappe/model/document.py", line 229, in insert
    self._validate_links()
  File "/home/goblin/frappe-bench/apps/frappe/frappe/model/document.py", line 827, in _validate_links
    frappe.throw(_("Could not find {0}").format(msg),
  File "/home/goblin/frappe-bench/apps/frappe/frappe/__init__.py", line 440, in throw
    msgprint(msg, raise_exception=exc, title=title, indicator='red', is_minimizable=is_minimizable, wide=wide, as_list=as_list)
  File "/home/goblin/frappe-bench/apps/frappe/frappe/__init__.py", line 419, in msgprint
    _raise_exception()
  File "/home/goblin/frappe-bench/apps/frappe/frappe/__init__.py", line 373, in _raise_exception
    raise raise_exception(msg)
frappe.exceptions.LinkValidationError: Could not find User Id: admin@goblin.com

Exception in thread Thread-1:
Traceback (most recent call last):
  File "/usr/lib/python3.9/threading.py", line 973, in _bootstrap_inner
    self.run()
  File "/home/goblin/frappe-bench/env/lib/python3.9/site-packages/redis/client.py", line 3718, in run
    pubsub.get_message(ignore_subscribe_messages=True,
  File "/home/goblin/frappe-bench/env/lib/python3.9/site-packages/redis/client.py", line 3617, in get_message
    response = self.parse_response(block=False, timeout=timeout)
  File "/home/goblin/frappe-bench/env/lib/python3.9/site-packages/redis/client.py", line 3503, in parse_response
Exception in thread Thread-1:
Traceback (most recent call last):
  File "/usr/lib/python3.9/threading.py", line 973, in _bootstrap_inner
    self.run()
  File "/home/goblin/frappe-bench/env/lib/python3.9/site-packages/redis/client.py", line 3718, in run
    pubsub.get_message(ignore_subscribe_messages=True,
  File "/home/goblin/frappe-bench/env/lib/python3.9/site-packages/redis/client.py", line 3617, in get_message
    response = self.parse_response(block=False, timeout=timeout)
  File "/home/goblin/frappe-bench/env/lib/python3.9/site-packages/redis/client.py", line 3503, in parse_response
    if not block and not conn.can_read(timeout=timeout):
  File "/home/goblin/frappe-bench/env/lib/python3.9/site-packages/redis/connection.py", line 734, in can_read
    return self._parser.can_read(timeout)
  File "/home/goblin/frappe-bench/env/lib/python3.9/site-packages/redis/connection.py", line 321, in can_read
    return self._buffer and self._buffer.can_read(timeout)
  File "/home/goblin/frappe-bench/env/lib/python3.9/site-packages/redis/connection.py", line 230, in can_read
    self._read_from_socket(timeout=timeout,
  File "/home/goblin/frappe-bench/env/lib/python3.9/site-packages/redis/connection.py", line 201, in _read_from_socket
    raise ConnectionError(SERVER_CLOSED_CONNECTION_ERROR)
redis.exceptions.ConnectionError: Connection closed by server.
    if not block and not conn.can_read(timeout=timeout):
  File "/home/goblin/frappe-bench/env/lib/python3.9/site-packages/redis/connection.py", line 734, in can_read
    return self._parser.can_read(timeout)
  File "/home/goblin/frappe-bench/env/lib/python3.9/site-packages/redis/connection.py", line 321, in can_read
    return self._buffer and self._buffer.can_read(timeout)
  File "/home/goblin/frappe-bench/env/lib/python3.9/site-packages/redis/connection.py", line 230, in can_read
    self._read_from_socket(timeout=timeout,
  File "/home/goblin/frappe-bench/env/lib/python3.9/site-packages/redis/connection.py", line 201, in _read_from_socket
    raise ConnectionError(SERVER_CLOSED_CONNECTION_ERROR)
redis.exceptions.ConnectionError: Connection closed by server.
Exception in thread Thread-1:
Traceback (most recent call last):
  File "/usr/lib/python3.9/threading.py", line 973, in _bootstrap_inner
Exception in thread Thread-1:
Traceback (most recent call last):
  File "/usr/lib/python3.9/threading.py", line 973, in _bootstrap_inner
    self.run()
  File "/home/goblin/frappe-bench/env/lib/python3.9/site-packages/redis/client.py", line 3718, in run
    self.run()
  File "/home/goblin/frappe-bench/env/lib/python3.9/site-packages/redis/client.py", line 3718, in run
    pubsub.get_message(ignore_subscribe_messages=True,
  File "/home/goblin/frappe-bench/env/lib/python3.9/site-packages/redis/client.py", line 3617, in get_message
    pubsub.get_message(ignore_subscribe_messages=True,
  File "/home/goblin/frappe-bench/env/lib/python3.9/site-packages/redis/client.py", line 3617, in get_message
    response = self.parse_response(block=False, timeout=timeout)
  File "/home/goblin/frappe-bench/env/lib/python3.9/site-packages/redis/client.py", line 3503, in parse_response
    response = self.parse_response(block=False, timeout=timeout)
  File "/home/goblin/frappe-bench/env/lib/python3.9/site-packages/redis/client.py", line 3503, in parse_response
        if not block and not conn.can_read(timeout=timeout):if not block and not conn.can_read(timeout=timeout):

  File "/home/goblin/frappe-bench/env/lib/python3.9/site-packages/redis/connection.py", line 734, in can_read
  File "/home/goblin/frappe-bench/env/lib/python3.9/site-packages/redis/connection.py", line 734, in can_read
        return self._parser.can_read(timeout)return self._parser.can_read(timeout)

  File "/home/goblin/frappe-bench/env/lib/python3.9/site-packages/redis/connection.py", line 321, in can_read
  File "/home/goblin/frappe-bench/env/lib/python3.9/site-packages/redis/connection.py", line 321, in can_read
        return self._buffer and self._buffer.can_read(timeout)return self._buffer and self._buffer.can_read(timeout)

  File "/home/goblin/frappe-bench/env/lib/python3.9/site-packages/redis/connection.py", line 230, in can_read
  File "/home/goblin/frappe-bench/env/lib/python3.9/site-packages/redis/connection.py", line 230, in can_read
        self._read_from_socket(timeout=timeout,self._read_from_socket(timeout=timeout,

  File "/home/goblin/frappe-bench/env/lib/python3.9/site-packages/redis/connection.py", line 201, in _read_from_socket
  File "/home/goblin/frappe-bench/env/lib/python3.9/site-packages/redis/connection.py", line 201, in _read_from_socket
        raise ConnectionError(SERVER_CLOSED_CONNECTION_ERROR)raise ConnectionError(SERVER_CLOSED_CONNECTION_ERROR)

redis.exceptionsredis.exceptions..ConnectionErrorConnectionError: : Connection closed by server.Connection closed by server.

Exception in thread Thread-1:
Traceback (most recent call last):
  File "/usr/lib/python3.9/threading.py", line 973, in _bootstrap_inner
    self.run()
  File "/home/goblin/frappe-bench/env/lib/python3.9/site-packages/redis/client.py", line 3718, in run
    pubsub.get_message(ignore_subscribe_messages=True,
  File "/home/goblin/frappe-bench/env/lib/python3.9/site-packages/redis/client.py", line 3617, in get_message
    response = self.parse_response(block=False, timeout=timeout)
  File "/home/goblin/frappe-bench/env/lib/python3.9/site-packages/redis/client.py", line 3503, in parse_response
    if not block and not conn.can_read(timeout=timeout):
  File "/home/goblin/frappe-bench/env/lib/python3.9/site-packages/redis/connection.py", line 734, in can_read
    return self._parser.can_read(timeout)
  File "/home/goblin/frappe-bench/env/lib/python3.9/site-packages/redis/connection.py", line 321, in can_read
    return self._buffer and self._buffer.can_read(timeout)
  File "/home/goblin/frappe-bench/env/lib/python3.9/site-packages/redis/connection.py", line 230, in can_read
    self._read_from_socket(timeout=timeout,
  File "/home/goblin/frappe-bench/env/lib/python3.9/site-packages/redis/connection.py", line 201, in _read_from_socket
    raise ConnectionError(SERVER_CLOSED_CONNECTION_ERROR)
redis.exceptions.ConnectionError: Connection closed by server.
Traceback (most recent call last):
  File "/home/goblin/frappe-bench/env/lib/python3.9/site-packages/redis/connection.py", line 559, in connect
    sock = self._connect()
  File "/home/goblin/frappe-bench/env/lib/python3.9/site-packages/redis/connection.py", line 615, in _connect
    raise err
  File "/home/goblin/frappe-bench/env/lib/python3.9/site-packages/redis/connection.py", line 603, in _connect
    sock.connect(socket_address)
ConnectionRefusedError: [Errno 111] Connection refused

During handling of the above exception, another exception occurred:

Traceback (most recent call last):
  File "/home/goblin/frappe-bench/env/lib/python3.9/site-packages/tenacity/__init__.py", line 407, in __call__
    result = fn(*args, **kwargs)
  File "/home/goblin/frappe-bench/apps/frappe/frappe/utils/background_jobs.py", line 265, in get_redis_conn
    redis_connection = RedisQueue.get_connection(**cred)
  File "/home/goblin/frappe-bench/apps/frappe/frappe/utils/redis_queue.py", line 24, in get_connection
    conn.ping()
  File "/home/goblin/frappe-bench/env/lib/python3.9/site-packages/redis/client.py", line 1378, in ping
    return self.execute_command('PING')
  File "/home/goblin/frappe-bench/env/lib/python3.9/site-packages/redis/client.py", line 898, in execute_command
    conn = self.connection or pool.get_connection(command_name, **options)
  File "/home/goblin/frappe-bench/env/lib/python3.9/site-packages/redis/connection.py", line 1192, in get_connection
    connection.connect()
  File "/home/goblin/frappe-bench/env/lib/python3.9/site-packages/redis/connection.py", line 563, in connect
    raise ConnectionError(self._error_message(e))
redis.exceptions.ConnectionError: Error 111 connecting to localhost:11000. Connection refused.

The above exception was the direct cause of the following exception:

Traceback (most recent call last):
  File "/usr/lib/python3.9/runpy.py", line 197, in _run_module_as_main
    return _run_code(code, main_globals, None,
  File "/usr/lib/python3.9/runpy.py", line 87, in _run_code
    exec(code, run_globals)
  File "/home/goblin/frappe-bench/apps/frappe/frappe/utils/bench_helper.py", line 104, in <module>
    main()
  File "/home/goblin/frappe-bench/apps/frappe/frappe/utils/bench_helper.py", line 18, in main
    click.Group(commands=commands)(prog_name='bench')
  File "/home/goblin/frappe-bench/env/lib/python3.9/site-packages/click/core.py", line 829, in __call__
    return self.main(*args, **kwargs)
  File "/home/goblin/frappe-bench/env/lib/python3.9/site-packages/click/core.py", line 782, in main
    rv = self.invoke(ctx)
  File "/home/goblin/frappe-bench/env/lib/python3.9/site-packages/click/core.py", line 1259, in invoke
    return _process_result(sub_ctx.command.invoke(sub_ctx))
  File "/home/goblin/frappe-bench/env/lib/python3.9/site-packages/click/core.py", line 1259, in invoke
    return _process_result(sub_ctx.command.invoke(sub_ctx))
  File "/home/goblin/frappe-bench/env/lib/python3.9/site-packages/click/core.py", line 1066, in invoke
    return ctx.invoke(self.callback, **ctx.params)
  File "/home/goblin/frappe-bench/env/lib/python3.9/site-packages/click/core.py", line 610, in invoke
    return callback(*args, **kwargs)
  File "/home/goblin/frappe-bench/apps/frappe/frappe/commands/scheduler.py", line 181, in start_worker
    start_worker(queue, quiet = quiet, rq_username=rq_username, rq_password=rq_password)
  File "/home/goblin/frappe-bench/apps/frappe/frappe/utils/background_jobs.py", line 147, in start_worker
    redis_connection = get_redis_conn(username=rq_username, password=rq_password)
  File "/home/goblin/frappe-bench/env/lib/python3.9/site-packages/tenacity/__init__.py", line 324, in wrapped_f
    return self(f, *args, **kw)
  File "/home/goblin/frappe-bench/env/lib/python3.9/site-packages/tenacity/__init__.py", line 404, in __call__
    do = self.iter(retry_state=retry_state)
  File "/home/goblin/frappe-bench/env/lib/python3.9/site-packages/tenacity/__init__.py", line 361, in iter
    raise retry_exc from fut.exception()
tenacity.RetryError: RetryError[<Future at 0x7f1a1b04ad30 state=finished raised ConnectionError>]
Traceback (most recent call last):
  File "/home/goblin/frappe-bench/env/lib/python3.9/site-packages/redis/connection.py", line 559, in connect
    sock = self._connect()
  File "/home/goblin/frappe-bench/env/lib/python3.9/site-packages/redis/connection.py", line 615, in _connect
    raise err
  File "/home/goblin/frappe-bench/env/lib/python3.9/site-packages/redis/connection.py", line 603, in _connect
    sock.connect(socket_address)
ConnectionRefusedError: [Errno 111] Connection refused

During handling of the above exception, another exception occurred:

Traceback (most recent call last):
  File "/home/goblin/frappe-bench/env/lib/python3.9/site-packages/tenacity/__init__.py", line 407, in __call__
    result = fn(*args, **kwargs)
  File "/home/goblin/frappe-bench/apps/frappe/frappe/utils/background_jobs.py", line 265, in get_redis_conn
    redis_connection = RedisQueue.get_connection(**cred)
  File "/home/goblin/frappe-bench/apps/frappe/frappe/utils/redis_queue.py", line 24, in get_connection
    conn.ping()
  File "/home/goblin/frappe-bench/env/lib/python3.9/site-packages/redis/client.py", line 1378, in ping
    return self.execute_command('PING')
  File "/home/goblin/frappe-bench/env/lib/python3.9/site-packages/redis/client.py", line 898, in execute_command
    conn = self.connection or pool.get_connection(command_name, **options)
  File "/home/goblin/frappe-bench/env/lib/python3.9/site-packages/redis/connection.py", line 1192, in get_connection
    connection.connect()
  File "/home/goblin/frappe-bench/env/lib/python3.9/site-packages/redis/connection.py", line 563, in connect
    raise ConnectionError(self._error_message(e))
redis.exceptions.ConnectionError: Error 111 connecting to localhost:11000. Connection refused.

The above exception was the direct cause of the following exception:

Traceback (most recent call last):
  File "/usr/lib/python3.9/runpy.py", line 197, in _run_module_as_main
    return _run_code(code, main_globals, None,
  File "/usr/lib/python3.9/runpy.py", line 87, in _run_code
    exec(code, run_globals)
  File "/home/goblin/frappe-bench/apps/frappe/frappe/utils/bench_helper.py", line 104, in <module>
    main()
  File "/home/goblin/frappe-bench/apps/frappe/frappe/utils/bench_helper.py", line 18, in main
    click.Group(commands=commands)(prog_name='bench')
  File "/home/goblin/frappe-bench/env/lib/python3.9/site-packages/click/core.py", line 829, in __call__
    return self.main(*args, **kwargs)
  File "/home/goblin/frappe-bench/env/lib/python3.9/site-packages/click/core.py", line 782, in main
    rv = self.invoke(ctx)
  File "/home/goblin/frappe-bench/env/lib/python3.9/site-packages/click/core.py", line 1259, in invoke
    return _process_result(sub_ctx.command.invoke(sub_ctx))
  File "/home/goblin/frappe-bench/env/lib/python3.9/site-packages/click/core.py", line 1259, in invoke
    return _process_result(sub_ctx.command.invoke(sub_ctx))
  File "/home/goblin/frappe-bench/env/lib/python3.9/site-packages/click/core.py", line 1066, in invoke
    return ctx.invoke(self.callback, **ctx.params)
  File "/home/goblin/frappe-bench/env/lib/python3.9/site-packages/click/core.py", line 610, in invoke
    return callback(*args, **kwargs)
  File "/home/goblin/frappe-bench/apps/frappe/frappe/commands/scheduler.py", line 181, in start_worker
    start_worker(queue, quiet = quiet, rq_username=rq_username, rq_password=rq_password)
  File "/home/goblin/frappe-bench/apps/frappe/frappe/utils/background_jobs.py", line 147, in start_worker
    redis_connection = get_redis_conn(username=rq_username, password=rq_password)
  File "/home/goblin/frappe-bench/env/lib/python3.9/site-packages/tenacity/__init__.py", line 324, in wrapped_f
    return self(f, *args, **kw)
  File "/home/goblin/frappe-bench/env/lib/python3.9/site-packages/tenacity/__init__.py", line 404, in __call__
    do = self.iter(retry_state=retry_state)
  File "/home/goblin/frappe-bench/env/lib/python3.9/site-packages/tenacity/__init__.py", line 361, in iter
    raise retry_exc from fut.exception()
tenacity.RetryError: RetryError[<Future at 0x7f23444bcd30 state=finished raised ConnectionError>]
Traceback (most recent call last):
  File "/home/goblin/frappe-bench/env/lib/python3.9/site-packages/redis/connection.py", line 559, in connect
    sock = self._connect()
  File "/home/goblin/frappe-bench/env/lib/python3.9/site-packages/redis/connection.py", line 615, in _connect
    raise err
  File "/home/goblin/frappe-bench/env/lib/python3.9/site-packages/redis/connection.py", line 603, in _connect
    sock.connect(socket_address)
ConnectionRefusedError: [Errno 111] Connection refused

During handling of the above exception, another exception occurred:

Traceback (most recent call last):
  File "/home/goblin/frappe-bench/env/lib/python3.9/site-packages/tenacity/__init__.py", line 407, in __call__
    result = fn(*args, **kwargs)
  File "/home/goblin/frappe-bench/apps/frappe/frappe/utils/background_jobs.py", line 265, in get_redis_conn
    redis_connection = RedisQueue.get_connection(**cred)
  File "/home/goblin/frappe-bench/apps/frappe/frappe/utils/redis_queue.py", line 24, in get_connection
    conn.ping()
  File "/home/goblin/frappe-bench/env/lib/python3.9/site-packages/redis/client.py", line 1378, in ping
    return self.execute_command('PING')
  File "/home/goblin/frappe-bench/env/lib/python3.9/site-packages/redis/client.py", line 898, in execute_command
    conn = self.connection or pool.get_connection(command_name, **options)
  File "/home/goblin/frappe-bench/env/lib/python3.9/site-packages/redis/connection.py", line 1192, in get_connection
    connection.connect()
  File "/home/goblin/frappe-bench/env/lib/python3.9/site-packages/redis/connection.py", line 563, in connect
    raise ConnectionError(self._error_message(e))
redis.exceptions.ConnectionError: Error 111 connecting to localhost:11000. Connection refused.

The above exception was the direct cause of the following exception:

Traceback (most recent call last):
  File "/usr/lib/python3.9/runpy.py", line 197, in _run_module_as_main
    return _run_code(code, main_globals, None,
  File "/usr/lib/python3.9/runpy.py", line 87, in _run_code
    exec(code, run_globals)
  File "/home/goblin/frappe-bench/apps/frappe/frappe/utils/bench_helper.py", line 104, in <module>
    main()
  File "/home/goblin/frappe-bench/apps/frappe/frappe/utils/bench_helper.py", line 18, in main
    click.Group(commands=commands)(prog_name='bench')
  File "/home/goblin/frappe-bench/env/lib/python3.9/site-packages/click/core.py", line 829, in __call__
    return self.main(*args, **kwargs)
  File "/home/goblin/frappe-bench/env/lib/python3.9/site-packages/click/core.py", line 782, in main
    rv = self.invoke(ctx)
  File "/home/goblin/frappe-bench/env/lib/python3.9/site-packages/click/core.py", line 1259, in invoke
    return _process_result(sub_ctx.command.invoke(sub_ctx))
  File "/home/goblin/frappe-bench/env/lib/python3.9/site-packages/click/core.py", line 1259, in invoke
    return _process_result(sub_ctx.command.invoke(sub_ctx))
  File "/home/goblin/frappe-bench/env/lib/python3.9/site-packages/click/core.py", line 1066, in invoke
    return ctx.invoke(self.callback, **ctx.params)
  File "/home/goblin/frappe-bench/env/lib/python3.9/site-packages/click/core.py", line 610, in invoke
    return callback(*args, **kwargs)
  File "/home/goblin/frappe-bench/apps/frappe/frappe/commands/scheduler.py", line 181, in start_worker
    start_worker(queue, quiet = quiet, rq_username=rq_username, rq_password=rq_password)
  File "/home/goblin/frappe-bench/apps/frappe/frappe/utils/background_jobs.py", line 147, in start_worker
    redis_connection = get_redis_conn(username=rq_username, password=rq_password)
  File "/home/goblin/frappe-bench/env/lib/python3.9/site-packages/tenacity/__init__.py", line 324, in wrapped_f
    return self(f, *args, **kw)
  File "/home/goblin/frappe-bench/env/lib/python3.9/site-packages/tenacity/__init__.py", line 404, in __call__
    do = self.iter(retry_state=retry_state)
  File "/home/goblin/frappe-bench/env/lib/python3.9/site-packages/tenacity/__init__.py", line 361, in iter
    raise retry_exc from fut.exception()
tenacity.RetryError: RetryError[<Future at 0x7fedf93dcd00 state=finished raised ConnectionError>]
Exception in thread Thread-1:
Traceback (most recent call last):
  File "/usr/lib/python3.9/threading.py", line 973, in _bootstrap_inner
    self.run()
  File "/home/goblin/frappe-bench/env/lib/python3.9/site-packages/redis/client.py", line 3718, in run
    pubsub.get_message(ignore_subscribe_messages=True,
  File "/home/goblin/frappe-bench/env/lib/python3.9/site-packages/redis/client.py", line 3617, in get_message
    response = self.parse_response(block=False, timeout=timeout)
  File "/home/goblin/frappe-bench/env/lib/python3.9/site-packages/redis/client.py", line 3503, in parse_response
    if not block and not conn.can_read(timeout=timeout):
  File "/home/goblin/frappe-bench/env/lib/python3.9/site-packages/redis/connection.py", line 734, in can_read
    return self._parser.can_read(timeout)
  File "/home/goblin/frappe-bench/env/lib/python3.9/site-packages/redis/connection.py", line 321, in can_read
    return self._buffer and self._buffer.can_read(timeout)
  File "/home/goblin/frappe-bench/env/lib/python3.9/site-packages/redis/connection.py", line 230, in can_read
    self._read_from_socket(timeout=timeout,
  File "/home/goblin/frappe-bench/env/lib/python3.9/site-packages/redis/connection.py", line 201, in _read_from_socket
    raise ConnectionError(SERVER_CLOSED_CONNECTION_ERROR)
redis.exceptions.ConnectionError: Connection closed by server.
Exception in thread Thread-1:
Traceback (most recent call last):
  File "/usr/lib/python3.9/threading.py", line 973, in _bootstrap_inner
    self.run()
  File "/home/goblin/frappe-bench/env/lib/python3.9/site-packages/redis/client.py", line 3718, in run
    pubsub.get_message(ignore_subscribe_messages=True,
  File "/home/goblin/frappe-bench/env/lib/python3.9/site-packages/redis/client.py", line 3617, in get_message
    response = self.parse_response(block=False, timeout=timeout)
  File "/home/goblin/frappe-bench/env/lib/python3.9/site-packages/redis/client.py", line 3503, in parse_response
    if not block and not conn.can_read(timeout=timeout):
  File "/home/goblin/frappe-bench/env/lib/python3.9/site-packages/redis/connection.py", line 734, in can_read
    return self._parser.can_read(timeout)
  File "/home/goblin/frappe-bench/env/lib/python3.9/site-packages/redis/connection.py", line 321, in can_read
    return self._buffer and self._buffer.can_read(timeout)
  File "/home/goblin/frappe-bench/env/lib/python3.9/site-packages/redis/connection.py", line 230, in can_read
    self._read_from_socket(timeout=timeout,
  File "/home/goblin/frappe-bench/env/lib/python3.9/site-packages/redis/connection.py", line 201, in _read_from_socket
    raise ConnectionError(SERVER_CLOSED_CONNECTION_ERROR)
redis.exceptions.ConnectionError: Connection closed by server.
Exception in thread Thread-1:
Traceback (most recent call last):
  File "/usr/lib/python3.9/threading.py", line 973, in _bootstrap_inner
    self.run()
  File "/home/goblin/frappe-bench/env/lib/python3.9/site-packages/redis/client.py", line 3718, in run
    pubsub.get_message(ignore_subscribe_messages=True,
  File "/home/goblin/frappe-bench/env/lib/python3.9/site-packages/redis/client.py", line 3617, in get_message
    response = self.parse_response(block=False, timeout=timeout)
  File "/home/goblin/frappe-bench/env/lib/python3.9/site-packages/redis/client.py", line 3503, in parse_response
    if not block and not conn.can_read(timeout=timeout):
  File "/home/goblin/frappe-bench/env/lib/python3.9/site-packages/redis/connection.py", line 734, in can_read
    return self._parser.can_read(timeout)
  File "/home/goblin/frappe-bench/env/lib/python3.9/site-packages/redis/connection.py", line 321, in can_read
    return self._buffer and self._buffer.can_read(timeout)
  File "/home/goblin/frappe-bench/env/lib/python3.9/site-packages/redis/connection.py", line 230, in can_read
    self._read_from_socket(timeout=timeout,
  File "/home/goblin/frappe-bench/env/lib/python3.9/site-packages/redis/connection.py", line 201, in _read_from_socket
    raise ConnectionError(SERVER_CLOSED_CONNECTION_ERROR)
redis.exceptions.ConnectionError: Connection closed by server.
Exception in thread Exception in thread Thread-1:
Thread-1Traceback (most recent call last):
:
  File "/usr/lib/python3.9/threading.py", line 973, in _bootstrap_inner
Traceback (most recent call last):
  File "/usr/lib/python3.9/threading.py", line 973, in _bootstrap_inner
        self.run()self.run()
  File "/home/goblin/frappe-bench/env/lib/python3.9/site-packages/redis/client.py", line 3718, in run

  File "/home/goblin/frappe-bench/env/lib/python3.9/site-packages/redis/client.py", line 3718, in run
Exception in thread Thread-1:
Traceback (most recent call last):
  File "/usr/lib/python3.9/threading.py", line 973, in _bootstrap_inner
    self.run()
  File "/home/goblin/frappe-bench/env/lib/python3.9/site-packages/redis/client.py", line 3718, in run
    pubsub.get_message(ignore_subscribe_messages=True,
  File "/home/goblin/frappe-bench/env/lib/python3.9/site-packages/redis/client.py", line 3617, in get_message
    pubsub.get_message(ignore_subscribe_messages=True,
  File "/home/goblin/frappe-bench/env/lib/python3.9/site-packages/redis/client.py", line 3617, in get_message
    response = self.parse_response(block=False, timeout=timeout)
  File "/home/goblin/frappe-bench/env/lib/python3.9/site-packages/redis/client.py", line 3503, in parse_response
    response = self.parse_response(block=False, timeout=timeout)
  File "/home/goblin/frappe-bench/env/lib/python3.9/site-packages/redis/client.py", line 3503, in parse_response
    pubsub.get_message(ignore_subscribe_messages=True,
  File "/home/goblin/frappe-bench/env/lib/python3.9/site-packages/redis/client.py", line 3617, in get_message
    response = self.parse_response(block=False, timeout=timeout)
  File "/home/goblin/frappe-bench/env/lib/python3.9/site-packages/redis/client.py", line 3503, in parse_response
    if not block and not conn.can_read(timeout=timeout):
  File "/home/goblin/frappe-bench/env/lib/python3.9/site-packages/redis/connection.py", line 734, in can_read
    return self._parser.can_read(timeout)
  File "/home/goblin/frappe-bench/env/lib/python3.9/site-packages/redis/connection.py", line 321, in can_read
    return self._buffer and self._buffer.can_read(timeout)
  File "/home/goblin/frappe-bench/env/lib/python3.9/site-packages/redis/connection.py", line 230, in can_read
    self._read_from_socket(timeout=timeout,
  File "/home/goblin/frappe-bench/env/lib/python3.9/site-packages/redis/connection.py", line 201, in _read_from_socket
    raise ConnectionError(SERVER_CLOSED_CONNECTION_ERROR)
redis.exceptions.ConnectionError: Connection closed by server.
    if not block and not conn.can_read(timeout=timeout):
  File "/home/goblin/frappe-bench/env/lib/python3.9/site-packages/redis/connection.py", line 734, in can_read
    return self._parser.can_read(timeout)
  File "/home/goblin/frappe-bench/env/lib/python3.9/site-packages/redis/connection.py", line 321, in can_read
    return self._buffer and self._buffer.can_read(timeout)
  File "/home/goblin/frappe-bench/env/lib/python3.9/site-packages/redis/connection.py", line 230, in can_read
    self._read_from_socket(timeout=timeout,
  File "/home/goblin/frappe-bench/env/lib/python3.9/site-packages/redis/connection.py", line 201, in _read_from_socket
    raise ConnectionError(SERVER_CLOSED_CONNECTION_ERROR)
redis.exceptions.ConnectionError: Connection closed by server.
    if not block and not conn.can_read(timeout=timeout):
  File "/home/goblin/frappe-bench/env/lib/python3.9/site-packages/redis/connection.py", line 734, in can_read
    return self._parser.can_read(timeout)
  File "/home/goblin/frappe-bench/env/lib/python3.9/site-packages/redis/connection.py", line 321, in can_read
    return self._buffer and self._buffer.can_read(timeout)
  File "/home/goblin/frappe-bench/env/lib/python3.9/site-packages/redis/connection.py", line 230, in can_read
    self._read_from_socket(timeout=timeout,
  File "/home/goblin/frappe-bench/env/lib/python3.9/site-packages/redis/connection.py", line 201, in _read_from_socket
    raise ConnectionError(SERVER_CLOSED_CONNECTION_ERROR)
redis.exceptions.ConnectionError: Connection closed by server.
Exception in thread Thread-1:
Traceback (most recent call last):
  File "/usr/lib/python3.9/threading.py", line 973, in _bootstrap_inner
    self.run()
  File "/home/goblin/frappe-bench/env/lib/python3.9/site-packages/redis/client.py", line 3718, in run
Exception in thread Thread-1:
Traceback (most recent call last):
  File "/usr/lib/python3.9/threading.py", line 973, in _bootstrap_inner
    self.run()
  File "/home/goblin/frappe-bench/env/lib/python3.9/site-packages/redis/client.py", line 3718, in run
Exception in thread Thread-1:
Traceback (most recent call last):
  File "/usr/lib/python3.9/threading.py", line 973, in _bootstrap_inner
    pubsub.get_message(ignore_subscribe_messages=True,
  File "/home/goblin/frappe-bench/env/lib/python3.9/site-packages/redis/client.py", line 3617, in get_message
    self.run()
  File "/home/goblin/frappe-bench/env/lib/python3.9/site-packages/redis/client.py", line 3718, in run
    response = self.parse_response(block=False, timeout=timeout)
  File "/home/goblin/frappe-bench/env/lib/python3.9/site-packages/redis/client.py", line 3503, in parse_response
    pubsub.get_message(ignore_subscribe_messages=True,
  File "/home/goblin/frappe-bench/env/lib/python3.9/site-packages/redis/client.py", line 3617, in get_message
    if not block and not conn.can_read(timeout=timeout):
  File "/home/goblin/frappe-bench/env/lib/python3.9/site-packages/redis/connection.py", line 734, in can_read
    return self._parser.can_read(timeout)
  File "/home/goblin/frappe-bench/env/lib/python3.9/site-packages/redis/connection.py", line 321, in can_read
    return self._buffer and self._buffer.can_read(timeout)
  File "/home/goblin/frappe-bench/env/lib/python3.9/site-packages/redis/connection.py", line 230, in can_read
    self._read_from_socket(timeout=timeout,
  File "/home/goblin/frappe-bench/env/lib/python3.9/site-packages/redis/connection.py", line 201, in _read_from_socket
    raise ConnectionError(SERVER_CLOSED_CONNECTION_ERROR)
redis.exceptions.ConnectionError: Connection closed by server.
    response = self.parse_response(block=False, timeout=timeout)
  File "/home/goblin/frappe-bench/env/lib/python3.9/site-packages/redis/client.py", line 3503, in parse_response
    if not block and not conn.can_read(timeout=timeout):
  File "/home/goblin/frappe-bench/env/lib/python3.9/site-packages/redis/connection.py", line 734, in can_read
    return self._parser.can_read(timeout)
  File "/home/goblin/frappe-bench/env/lib/python3.9/site-packages/redis/connection.py", line 321, in can_read
    return self._buffer and self._buffer.can_read(timeout)
  File "/home/goblin/frappe-bench/env/lib/python3.9/site-packages/redis/connection.py", line 230, in can_read
    pubsub.get_message(ignore_subscribe_messages=True,
  File "/home/goblin/frappe-bench/env/lib/python3.9/site-packages/redis/client.py", line 3617, in get_message
    response = self.parse_response(block=False, timeout=timeout)
  File "/home/goblin/frappe-bench/env/lib/python3.9/site-packages/redis/client.py", line 3503, in parse_response
    if not block and not conn.can_read(timeout=timeout):
  File "/home/goblin/frappe-bench/env/lib/python3.9/site-packages/redis/connection.py", line 734, in can_read
    return self._parser.can_read(timeout)
  File "/home/goblin/frappe-bench/env/lib/python3.9/site-packages/redis/connection.py", line 321, in can_read
    return self._buffer and self._buffer.can_read(timeout)
  File "/home/goblin/frappe-bench/env/lib/python3.9/site-packages/redis/connection.py", line 230, in can_read
    self._read_from_socket(timeout=timeout,
  File "/home/goblin/frappe-bench/env/lib/python3.9/site-packages/redis/connection.py", line 201, in _read_from_socket
    raise ConnectionError(SERVER_CLOSED_CONNECTION_ERROR)
redis.exceptions.ConnectionError: Connection closed by server.
    self._read_from_socket(timeout=timeout,
  File "/home/goblin/frappe-bench/env/lib/python3.9/site-packages/redis/connection.py", line 201, in _read_from_socket
    raise ConnectionError(SERVER_CLOSED_CONNECTION_ERROR)
redis.exceptions.ConnectionError: Connection closed by server.
Exception in thread Thread-1:
Traceback (most recent call last):
  File "/usr/lib/python3.9/threading.py", line 973, in _bootstrap_inner
    self.run()
  File "/home/goblin/frappe-bench/env/lib/python3.9/site-packages/redis/client.py", line 3718, in run
    pubsub.get_message(ignore_subscribe_messages=True,
  File "/home/goblin/frappe-bench/env/lib/python3.9/site-packages/redis/client.py", line 3617, in get_message
    response = self.parse_response(block=False, timeout=timeout)
  File "/home/goblin/frappe-bench/env/lib/python3.9/site-packages/redis/client.py", line 3503, in parse_response
    if not block and not conn.can_read(timeout=timeout):
  File "/home/goblin/frappe-bench/env/lib/python3.9/site-packages/redis/connection.py", line 734, in can_read
    return self._parser.can_read(timeout)
  File "/home/goblin/frappe-bench/env/lib/python3.9/site-packages/redis/connection.py", line 321, in can_read
    return self._buffer and self._buffer.can_read(timeout)
  File "/home/goblin/frappe-bench/env/lib/python3.9/site-packages/redis/connection.py", line 230, in can_read
    self._read_from_socket(timeout=timeout,
  File "/home/goblin/frappe-bench/env/lib/python3.9/site-packages/redis/connection.py", line 201, in _read_from_socket
    raise ConnectionError(SERVER_CLOSED_CONNECTION_ERROR)
redis.exceptions.ConnectionError: Connection closed by server.
